{"error":"An unexpected error occurred: RetryError[<Future at 0xffffa494ffd0 state=finished raised ValueError>]"}
